Workbook

Sheet Dashboard
A1: E-Commerce Scaling Dashboard Meta Ads CPA scenarios, reinvestment pacing, and monthly profit roadmap | B1: E-Commerce Scaling Dashboard Meta Ads CPA scenarios, reinvestment pacing, and monthly profit roadmap | C1: E-Commerce Scaling Dashboard Meta Ads CPA scenarios, reinvestment pacing, and monthly profit roadmap | D1: E-Commerce Scaling Dashboard Meta Ads CPA scenarios, reinvestment pacing, and monthly profit roadmap | E1: E-Commerce Scaling Dashboard Meta Ads CPA scenarios, reinvestment pacing, and monthly profit roadmap | F1: E-Commerce Scaling Dashboard Meta Ads CPA scenarios, reinvestment pacing, and monthly profit roadmap | G1: E-Commerce Scaling Dashboard Meta Ads CPA scenarios, reinvestment pacing, and monthly profit roadmap | H1: E-Commerce Scaling Dashboard Meta Ads CPA scenarios, reinvestment pacing, and monthly profit roadmap | I1: E-Commerce Scaling Dashboard Meta Ads CPA scenarios, reinvestment pacing, and monthly profit roadmap | J1: E-Commerce Scaling Dashboard Meta Ads CPA scenarios, reinvestment pacing, and monthly profit roadmap | K1: E-Commerce Scaling Dashboard Meta Ads CPA scenarios, reinvestment pacing, and monthly profit roadmap | L1: E-Commerce Scaling Dashboard Meta Ads CPA scenarios, reinvestment pacing, and monthly profit roadmap
A2: E-Commerce Scaling Dashboard Meta Ads CPA scenarios, reinvestment pacing, and monthly profit roadmap | B2: E-Commerce Scaling Dashboard Meta Ads CPA scenarios, reinvestment pacing, and monthly profit roadmap | C2: E-Commerce Scaling Dashboard Meta Ads CPA scenarios, reinvestment pacing, and monthly profit roadmap | D2: E-Commerce Scaling Dashboard Meta Ads CPA scenarios, reinvestment pacing, and monthly profit roadmap | E2: E-Commerce Scaling Dashboard Meta Ads CPA scenarios, reinvestment pacing, and monthly profit roadmap | F2: E-Commerce Scaling Dashboard Meta Ads CPA scenarios, reinvestment pacing, and monthly profit roadmap | G2: E-Commerce Scaling Dashboard Meta Ads CPA scenarios, reinvestment pacing, and monthly profit roadmap | H2: E-Commerce Scaling Dashboard Meta Ads CPA scenarios, reinvestment pacing, and monthly profit roadmap | I2: E-Commerce Scaling Dashboard Meta Ads CPA scenarios, reinvestment pacing, and monthly profit roadmap | J2: E-Commerce Scaling Dashboard Meta Ads CPA scenarios, reinvestment pacing, and monthly profit roadmap | K2: E-Commerce Scaling Dashboard Meta Ads CPA scenarios, reinvestment pacing, and monthly profit roadmap | L2: E-Commerce Scaling Dashboard Meta Ads CPA scenarios, reinvestment pacing, and monthly profit roadmap
A4: Model Snapshot | B4: Model Snapshot | C4: Model Snapshot | D4: Model Snapshot | E4: Model Snapshot | F4: Model Snapshot | G4: Model Snapshot | H4: Model Snapshot | I4: Model Snapshot | J4: Model Snapshot | K4: Model Snapshot | L4: Model Snapshot
A5: Metric | B5: Value | C5: Metric | D5: Value | E5: Metric | F5: Value | G5: Metric | H5: Value | I5: Metric | J5: Value | K5: Metric | L5: Value
A6: Product | B6: =Inputs!B6 -> Sample Product | C6: Selling price | D6: =Inputs!B7 -> 300 | E6: Starting units | F6: =Inputs!B8 -> 75 | G6: Var cost pre-ads | H6: =Inputs!B24 -> 200 | I6: Break-even CPA | J6: =Inputs!B25 -> 100 | K6: Model status | L6: =Checks!F3 -> Review
A7: M12 best profit | B7: =MAX('Scenario Matrix'!H6:H14) -> 6025 | C7: Best scenario | D7: =INDEX('Scenario Matrix'!A6:A14,MATCH(MAX('Scenario Matrix'!H6:H14),'Scenario Matrix'!H6:H14,0)) -> Good / 70% | E7: M12 best units | F7: =INDEX('Scenario Matrix'!G6:G14,MATCH(MAX('Scenario Matrix'!H6:H14),'Scenario Matrix'!H6:H14,0)) -> 241 | G7: Best cum. profit | H7: =MAX('Scenario Matrix'!I6:I14) -> 42800 | I7: Startup cash | J7: ='Cost Builder'!C13 -> 11250 | K7: Break-even ROAS | L7: ='Cost Builder'!C10 -> 3
A8: Bad CPA | B8: =Inputs!C29 -> 126 | C8: Base CPA | D8: =Inputs!C30 -> 96 | E8: Good CPA | F8: =Inputs!C31 -> 66 | G8: Bad reinvest | H8: =Inputs!D29 -> 0.3 | I8: Base reinvest | J8: =Inputs!D30 -> 0.5 | K8: Good reinvest | L8: =Inputs!D31 -> 0.7
A10: Default Scenario Outcomes | B10: Default Scenario Outcomes | C10: Default Scenario Outcomes | D10: Default Scenario Outcomes | E10: Default Scenario Outcomes | F10: Default Scenario Outcomes | H10: How to Use | I10: How to Use | J10: How to Use | K10: How to Use | L10: How to Use
A11: Scenario | B11: CPA | C11: Reinvest % | D11: M12 units | E11: M12 net profit | F11: Cumulative net profit | H11: 1 | I11: Edit yellow cells on Inputs
A12: Bad / 30% | B12: ='Scenario Matrix'!C6 -> 126 | C12: ='Scenario Matrix'!D6 -> 0.3 | D12: ='Scenario Matrix'!G6 -> 75 | E12: ='Scenario Matrix'!H6 -> -2625 | F12: ='Scenario Matrix'!I6 -> -31500 | H12: 2 | I12: Use CPA % or overwrite CPA values if your Ads Manager data is stronger
A13: Base / 50% | B13: ='Scenario Matrix'!C10 -> 96 | C13: ='Scenario Matrix'!D10 -> 0.5 | D13: ='Scenario Matrix'!G10 -> 75 | E13: ='Scenario Matrix'!H10 -> -375 | F13: ='Scenario Matrix'!I10 -> -4500 | H13: 3 | I13: Roadmap shows month-by-month cash kept, reinvested profit, and added stock
A14: Good / 70% | B14: ='Scenario Matrix'!C14 -> 66 | C14: ='Scenario Matrix'!D14 -> 0.7 | D14: ='Scenario Matrix'!G14 -> 241 | E14: ='Scenario Matrix'!H14 -> 6025 | F14: ='Scenario Matrix'!I14 -> 42800 | H14: 4 | I14: Scenario Matrix compares CPA case x 30/50/70% reinvestment
H15: 5 | I15: Checks tab warns when CPA or margin assumptions break the model
A17: Chart Data: Net Profit by Month | B17: Chart Data: Net Profit by Month | C17: Chart Data: Net Profit by Month | D17: Chart Data: Net Profit by Month
A18: Month | B18: Bad / 30% | C18: Base / 50% | D18: Good / 70%
A19: M1 | B19: =Roadmap!B12 -> -2625 | C19: =Roadmap!B31 -> -375 | D19: =Roadmap!B50 -> 1875
A20: M2 | B20: =Roadmap!C12 -> -2625 | C20: =Roadmap!C31 -> -375 | D20: =Roadmap!C50 -> 2075
A21: M3 | B21: =Roadmap!D12 -> -2625 | C21: =Roadmap!D31 -> -375 | D21: =Roadmap!D50 -> 2300
A22: M4 | B22: =Roadmap!E12 -> -2625 | C22: =Roadmap!E31 -> -375 | D22: =Roadmap!E50 -> 2550
A23: M5 | B23: =Roadmap!F12 -> -2625 | C23: =Roadmap!F31 -> -375 | D23: =Roadmap!F50 -> 2825
A24: M6 | B24: =Roadmap!G12 -> -2625 | C24: =Roadmap!G31 -> -375 | D24: =Roadmap!G50 -> 3150
A25: M7 | B25: =Roadmap!H12 -> -2625 | C25: =Roadmap!H31 -> -375 | D25: =Roadmap!H50 -> 3500
A26: M8 | B26: =Roadmap!I12 -> -2625 | C26: =Roadmap!I31 -> -375 | D26: =Roadmap!I50 -> 3900
A27: M9 | B27: =Roadmap!J12 -> -2625 | C27: =Roadmap!J31 -> -375 | D27: =Roadmap!J50 -> 4350
A28: M10 | B28: =Roadmap!K12 -> -2625 | C28: =Roadmap!K31 -> -375 | D28: =Roadmap!K50 -> 4850
A29: M11 | B29: =Roadmap!L12 -> -2625 | C29: =Roadmap!L31 -> -375 | D29: =Roadmap!L50 -> 5400
A30: M12 | B30: =Roadmap!M12 -> -2625 | C30: =Roadmap!M31 -> -375 | D30: =Roadmap!M50 -> 6025
A33: Chart Data: Month 12 Units | B33: Chart Data: Month 12 Units | C33: Chart Data: Month 12 Units | D33: Chart Data: Month 12 Units
A34: Scenario | B34: M12 units | C34: M12 net profit | D34: Cumulative net profit
A35: Bad / 30% | B35: ='Scenario Matrix'!G6 -> 75 | C35: ='Scenario Matrix'!H6 -> -2625 | D35: ='Scenario Matrix'!I6 -> -31500
A36: Base / 50% | B36: ='Scenario Matrix'!G10 -> 75 | C36: ='Scenario Matrix'!H10 -> -375 | D36: ='Scenario Matrix'!I10 -> -4500
A37: Good / 70% | B37: ='Scenario Matrix'!G14 -> 241 | C37: ='Scenario Matrix'!H14 -> 6025 | D37: ='Scenario Matrix'!I14 -> 42800

Sheet Inputs
A1: E-Commerce Scaling Roadmap Editable assumptions for Chinese sourcing, branding, and Meta Ads CPA scenarios | B1: E-Commerce Scaling Roadmap Editable assumptions for Chinese sourcing, branding, and Meta Ads CPA scenarios | C1: E-Commerce Scaling Roadmap Editable assumptions for Chinese sourcing, branding, and Meta Ads CPA scenarios | D1: E-Commerce Scaling Roadmap Editable assumptions for Chinese sourcing, branding, and Meta Ads CPA scenarios | E1: E-Commerce Scaling Roadmap Editable assumptions for Chinese sourcing, branding, and Meta Ads CPA scenarios | F1: E-Commerce Scaling Roadmap Editable assumptions for Chinese sourcing, branding, and Meta Ads CPA scenarios | G1: E-Commerce Scaling Roadmap Editable assumptions for Chinese sourcing, branding, and Meta Ads CPA scenarios | H1: E-Commerce Scaling Roadmap Editable assumptions for Chinese sourcing, branding, and Meta Ads CPA scenarios
A2: E-Commerce Scaling Roadmap Editable assumptions for Chinese sourcing, branding, and Meta Ads CPA scenarios | B2: E-Commerce Scaling Roadmap Editable assumptions for Chinese sourcing, branding, and Meta Ads CPA scenarios | C2: E-Commerce Scaling Roadmap Editable assumptions for Chinese sourcing, branding, and Meta Ads CPA scenarios | D2: E-Commerce Scaling Roadmap Editable assumptions for Chinese sourcing, branding, and Meta Ads CPA scenarios | E2: E-Commerce Scaling Roadmap Editable assumptions for Chinese sourcing, branding, and Meta Ads CPA scenarios | F2: E-Commerce Scaling Roadmap Editable assumptions for Chinese sourcing, branding, and Meta Ads CPA scenarios | G2: E-Commerce Scaling Roadmap Editable assumptions for Chinese sourcing, branding, and Meta Ads CPA scenarios | H2: E-Commerce Scaling Roadmap Editable assumptions for Chinese sourcing, branding, and Meta Ads CPA scenarios
A4: 1) Product and Sales Setup | B4: 1) Product and Sales Setup | C4: 1) Product and Sales Setup | D4: 1) Product and Sales Setup | E4: 1) Product and Sales Setup | F4: 1) Product and Sales Setup | G4: 1) Product and Sales Setup | H4: 1) Product and Sales Setup
A5: Input | B5: Value | C5: Notes | E5: Model Color Key | F5: Model Color Key | G5: Model Color Key | H5: Model Color Key
A6: Product / Brand name | B6: Sample Product | C6: Change to your actual product name | E6: Cell type | F6: Meaning | G6: Example | H6: Action
A7: Selling price / unit | B7: 300 | C7: Target product price in THB | E7: Yellow + blue text | F7: Editable assumption | G7: Price/cost/CPA | H7: Change these
A8: Month 1 order units | B8: 75 | C8: Starting inventory volume | E8: Black text | F8: Formula output | G8: Profit, ROAS, MER | H8: Do not overwrite unless needed
A9: Forecast months | B9: 12 | C9: Model is built for 12 months | E9: Green text | F9: Linked output | G9: Dashboard refs | H9: Trace back to source tab
A10: Sell-through rate | B10: 1 | C10: Share of ordered units sold each month
A11: Refund / return rate | B11: 0.03 | C11: Revenue leakage from returns/refunds | E11: 3) CPA and Reinvestment Scenarios | F11: 3) CPA and Reinvestment Scenarios | G11: 3) CPA and Reinvestment Scenarios | H11: 3) CPA and Reinvestment Scenarios
A12: Monthly fixed overhead | B12: 0 | C12: Tools, staff, agency, samples, warehouse, etc. | E12: Scenario | F12: CPA % of price | G12: CPA / purchase | H12: Profit reinvested into new inventory
A13: Max monthly order growth | B13: 0.5 | C13: Operational cap so reinvestment scaling stays realistic | E13: Bad CPA | F13: 0.42 | G13: =ROUND($B$7*F13,0) -> 126 | H13: 0.3
A14: 2) Variable Cost per Unit Before Ads | B14: 2) Variable Cost per Unit Before Ads | C14: 2) Variable Cost per Unit Before Ads | E14: Base CPA | F14: 0.32 | G14: =ROUND($B$7*F14,0) -> 96 | H14: 0.5
A15: Input | B15: Value | C15: Notes | E15: Good CPA | F15: 0.22 | G15: =ROUND($B$7*F15,0) -> 66 | H15: 0.7
A16: Landed product cost / unit | B16: 150 | C16: Factory cost + China shipping + import duty + local freight to you | E16: Break-even CPA | F16: =$B$25/$B$7 -> 0.33333333 | G16: =$B$25 -> 100 | H16: CPA <= gross profit before ads
A17: Packaging / unit | B17: 10 | C17: Box, pouch, insert, label, tape
A18: Fulfillment / unit | B18: 10 | C18: Pick, pack, warehouse handling | E18: 4) Price-Tier CPA Guide | F18: 4) Price-Tier CPA Guide | G18: 4) Price-Tier CPA Guide | H18: 4) Price-Tier CPA Guide
A19: Shipping to customer / unit | B19: 30 | C19: Last-mile delivery paid by seller | E19: Price tier | F19: Good CPA | G19: Base CPA | H19: Bad CPA / danger zone
A20: Affiliate commission / unit | B20: 0 | C20: Use 0 if none | E20: 600-900 THB | F20: 120-220 | G20: 220-320 | H20: 350+
A21: Payment / platform fixed fee / unit | B21: 0 | C21: COD/payment/marketplace fixed fee | E21: 900-1,300 THB | F21: 180-330 | G21: 330-480 | H21: 500-600+
A22: Payment / platform fee % of price | B22: 0 | C22: Percentage fee applied to selling price | E22: Formula used here | F22: Price x 22% | G22: Price x 32% | H22: Price x 42%
A23: Other variable cost / unit | B23: 0 | C23: Samples, warranty reserve, inserts, extra fee
A24: Total variable cost before ads | B24: =SUM(B16:B21)+B7*B22+B23 -> 200 | C24: Formula
A25: Gross profit before ads / unit | B25: =B7-B24 -> 100 | C25: Formula
A27: 5) Scenario Table Used by the Model | B27: 5) Scenario Table Used by the Model | C27: 5) Scenario Table Used by the Model | D27: 5) Scenario Table Used by the Model | E27: 5) Scenario Table Used by the Model | F27: 5) Scenario Table Used by the Model | G27: 5) Scenario Table Used by the Model | H27: 5) Scenario Table Used by the Model
A28: Scenario | B28: CPA % | C28: CPA | D28: Reinvest % | E28: Net profit / unit | F28: ROAS | G28: MER | H28: CPA cushion vs break-even
A29: Bad CPA | B29: =F13 -> 0.42 | C29: =G13 -> 126 | D29: =H13 -> 0.3 | E29: =$B$25-C29 -> -26 | F29: =$B$7/C29 -> 2.3809524 | G29: =C29/$B$7 -> 0.42 | H29: =$B$25-C29 -> -26
A30: Base CPA | B30: =F14 -> 0.32 | C30: =G14 -> 96 | D30: =H14 -> 0.5 | E30: =$B$25-C30 -> 4 | F30: =$B$7/C30 -> 3.125 | G30: =C30/$B$7 -> 0.32 | H30: =$B$25-C30 -> 4
A31: Good CPA | B31: =F15 -> 0.22 | C31: =G15 -> 66 | D31: =H15 -> 0.7 | E31: =$B$25-C31 -> 34 | F31: =$B$7/C31 -> 4.5454545 | G31: =C31/$B$7 -> 0.22 | H31: =$B$25-C31 -> 34
A32: Break-even | B32: =F16 -> 0.33333333 | C32: =G16 -> 100 | E32: =$B$25-C32 -> 0 | F32: =$B$7/C32 -> 3 | G32: =C32/$B$7 -> 0.33333333 | H32: =$B$25-C32 -> 0

Sheet Cost Builder
A1: Unit Economics and Break-Even Math Per-unit profit model adapted from the source workbook logic | B1: Unit Economics and Break-Even Math Per-unit profit model adapted from the source workbook logic | C1: Unit Economics and Break-Even Math Per-unit profit model adapted from the source workbook logic | D1: Unit Economics and Break-Even Math Per-unit profit model adapted from the source workbook logic | E1: Unit Economics and Break-Even Math Per-unit profit model adapted from the source workbook logic | F1: Unit Economics and Break-Even Math Per-unit profit model adapted from the source workbook logic | G1: Unit Economics and Break-Even Math Per-unit profit model adapted from the source workbook logic | H1: Unit Economics and Break-Even Math Per-unit profit model adapted from the source workbook logic
A2: Unit Economics and Break-Even Math Per-unit profit model adapted from the source workbook logic | B2: Unit Economics and Break-Even Math Per-unit profit model adapted from the source workbook logic | C2: Unit Economics and Break-Even Math Per-unit profit model adapted from the source workbook logic | D2: Unit Economics and Break-Even Math Per-unit profit model adapted from the source workbook logic | E2: Unit Economics and Break-Even Math Per-unit profit model adapted from the source workbook logic | F2: Unit Economics and Break-Even Math Per-unit profit model adapted from the source workbook logic | G2: Unit Economics and Break-Even Math Per-unit profit model adapted from the source workbook logic | H2: Unit Economics and Break-Even Math Per-unit profit model adapted from the source workbook logic
A4: Core Unit Economics | B4: Core Unit Economics | C4: Core Unit Economics | D4: Core Unit Economics | E4: Core Unit Economics | F4: Core Unit Economics | G4: Core Unit Economics | H4: Core Unit Economics | J4: Quick Interpretation
A5: Metric | B5: Formula / Link | C5: Value | D5: Notes | E5: Bad CPA | F5: Base CPA | G5: Good CPA | H5: Break-even | J5: If Net profit / unit is positive | K5: You can scale, then watch cash conversion and stock lead time
A6: Selling price | B6: Inputs!B7 | C6: =Inputs!B7 -> 300 | D6: Revenue per unit | E6: =Inputs!C29 -> 126 | F6: =Inputs!C30 -> 96 | G6: =Inputs!C31 -> 66 | H6: =Inputs!C32 -> 100 | J6: If CPA cushion is small | K6: Scale slowly or raise price / bundle / lower variable costs
A7: Variable cost before ads | B7: Inputs!B24 | C7: =Inputs!B24 -> 200 | D7: Landed cost + ops + payment/platform fees | E7: =Inputs!B24 -> 200 | F7: =Inputs!B24 -> 200 | G7: =Inputs!B24 -> 200 | H7: =Inputs!B24 -> 200 | J7: If ROAS is above break-even | K7: Campaign can be profitable before fixed overhead
A8: Gross profit before ads | B8: Inputs!B25 | C8: =Inputs!B25 -> 100 | D8: Maximum CPA before fixed overhead | E8: =Inputs!B7-Inputs!B24-E6 -> -26 | F8: =Inputs!B7-Inputs!B24-F6 -> 4 | G8: =Inputs!B7-Inputs!B24-G6 -> 34 | H8: =Inputs!B7-Inputs!B24-H6 -> 0 | J8: If MER is too high | K8: Ads are consuming too much revenue
A9: COGS % before ads | B9: Inputs!B24 / Inputs!B7 | C9: =Inputs!B24/Inputs!B7 -> 0.66666667 | D9: Variable cost share of price | E9: =Inputs!B24/Inputs!B7 -> 0.66666667 | F9: =Inputs!B24/Inputs!B7 -> 0.66666667 | G9: =Inputs!B24/Inputs!B7 -> 0.66666667 | H9: =Inputs!B24/Inputs!B7 -> 0.66666667
A10: Break-even ROAS | B10: Price / gross profit before ads | C10: =Inputs!B7/Inputs!B25 -> 3 | D10: ROAS below this loses money | E10: =Inputs!B7/E6 -> 2.3809524 | F10: =Inputs!B7/F6 -> 3.125 | G10: =Inputs!B7/G6 -> 4.5454545 | H10: =Inputs!B7/H6 -> 3
A11: Break-even CPA | B11: Gross profit before ads | C11: =Inputs!B25 -> 100 | D11: CPA threshold before fixed overhead | E11: =Inputs!B25-E6 -> -26 | F11: =Inputs!B25-F6 -> 4 | G11: =Inputs!B25-G6 -> 34 | H11: =Inputs!B25-H6 -> 0
A12: Monthly fixed overhead | B12: Inputs!B12 | C12: =Inputs!B12 -> 0 | D12: Allocated after unit economics | E12: =Inputs!B12 -> 0 | F12: =Inputs!B12 -> 0 | G12: =Inputs!B12 -> 0 | H12: =Inputs!B12 -> 0
A13: Month 1 startup product cash | B13: Initial units x landed cost | C13: =Inputs!B8*Inputs!B16 -> 11250 | D13: Inventory cash needed before ad spend | E13: =Inputs!B8*Inputs!B16 -> 11250 | F13: =Inputs!B8*Inputs!B16 -> 11250 | G13: =Inputs!B8*Inputs!B16 -> 11250 | H13: =Inputs!B8*Inputs!B16 -> 11250
A16: Contribution Margin by Scenario | B16: Contribution Margin by Scenario | C16: Contribution Margin by Scenario | D16: Contribution Margin by Scenario | E16: Contribution Margin by Scenario | F16: Contribution Margin by Scenario | G16: Contribution Margin by Scenario | H16: Contribution Margin by Scenario
A17: Scenario | B17: Price | C17: Cost before ads | D17: CPA | E17: Net profit / unit | F17: Net margin | G17: ROAS | H17: MER
A18: Bad CPA | B18: =Inputs!B7 -> 300 | C18: =Inputs!B24 -> 200 | D18: =Inputs!C29 -> 126 | E18: =B18-C18-D18 -> -26 | F18: =E18/B18 -> -0.086666667 | G18: =B18/D18 -> 2.3809524 | H18: =D18/B18 -> 0.42
A19: Base CPA | B19: =Inputs!B7 -> 300 | C19: =Inputs!B24 -> 200 | D19: =Inputs!C30 -> 96 | E19: =B19-C19-D19 -> 4 | F19: =E19/B19 -> 0.013333333 | G19: =B19/D19 -> 3.125 | H19: =D19/B19 -> 0.32
A20: Good CPA | B20: =Inputs!B7 -> 300 | C20: =Inputs!B24 -> 200 | D20: =Inputs!C31 -> 66 | E20: =B20-C20-D20 -> 34 | F20: =E20/B20 -> 0.11333333 | G20: =B20/D20 -> 4.5454545 | H20: =D20/B20 -> 0.22
A21: Break-even | B21: =Inputs!B7 -> 300 | C21: =Inputs!B24 -> 200 | D21: =Inputs!C32 -> 100 | E21: =B21-C21-D21 -> 0 | F21: =E21/B21 -> 0 | G21: =B21/D21 -> 3 | H21: =D21/B21 -> 0.33333333

Sheet Roadmap
A1: 12-Month Scaling Roadmap Each scenario starts with Month 1 inventory, then reinvests a % of monthly profit into more stock for the next month | B1: 12-Month Scaling Roadmap Each scenario starts with Month 1 inventory, then reinvests a % of monthly profit into more stock for the next month | C1: 12-Month Scaling Roadmap Each scenario starts with Month 1 inventory, then reinvests a % of monthly profit into more stock for the next month | D1: 12-Month Scaling Roadmap Each scenario starts with Month 1 inventory, then reinvests a % of monthly profit into more stock for the next month | E1: 12-Month Scaling Roadmap Each scenario starts with Month 1 inventory, then reinvests a % of monthly profit into more stock for the next month | F1: 12-Month Scaling Roadmap Each scenario starts with Month 1 inventory, then reinvests a % of monthly profit into more stock for the next month | G1: 12-Month Scaling Roadmap Each scenario starts with Month 1 inventory, then reinvests a % of monthly profit into more stock for the next month | H1: 12-Month Scaling Roadmap Each scenario starts with Month 1 inventory, then reinvests a % of monthly profit into more stock for the next month | I1: 12-Month Scaling Roadmap Each scenario starts with Month 1 inventory, then reinvests a % of monthly profit into more stock for the next month | J1: 12-Month Scaling Roadmap Each scenario starts with Month 1 inventory, then reinvests a % of monthly profit into more stock for the next month | K1: 12-Month Scaling Roadmap Each scenario starts with Month 1 inventory, then reinvests a % of monthly profit into more stock for the next month | L1: 12-Month Scaling Roadmap Each scenario starts with Month 1 inventory, then reinvests a % of monthly profit into more stock for the next month | M1: 12-Month Scaling Roadmap Each scenario starts with Month 1 inventory, then reinvests a % of monthly profit into more stock for the next month
A2: 12-Month Scaling Roadmap Each scenario starts with Month 1 inventory, then reinvests a % of monthly profit into more stock for the next month | B2: 12-Month Scaling Roadmap Each scenario starts with Month 1 inventory, then reinvests a % of monthly profit into more stock for the next month | C2: 12-Month Scaling Roadmap Each scenario starts with Month 1 inventory, then reinvests a % of monthly profit into more stock for the next month | D2: 12-Month Scaling Roadmap Each scenario starts with Month 1 inventory, then reinvests a % of monthly profit into more stock for the next month | E2: 12-Month Scaling Roadmap Each scenario starts with Month 1 inventory, then reinvests a % of monthly profit into more stock for the next month | F2: 12-Month Scaling Roadmap Each scenario starts with Month 1 inventory, then reinvests a % of monthly profit into more stock for the next month | G2: 12-Month Scaling Roadmap Each scenario starts with Month 1 inventory, then reinvests a % of monthly profit into more stock for the next month | H2: 12-Month Scaling Roadmap Each scenario starts with Month 1 inventory, then reinvests a % of monthly profit into more stock for the next month | I2: 12-Month Scaling Roadmap Each scenario starts with Month 1 inventory, then reinvests a % of monthly profit into more stock for the next month | J2: 12-Month Scaling Roadmap Each scenario starts with Month 1 inventory, then reinvests a % of monthly profit into more stock for the next month | K2: 12-Month Scaling Roadmap Each scenario starts with Month 1 inventory, then reinvests a % of monthly profit into more stock for the next month | L2: 12-Month Scaling Roadmap Each scenario starts with Month 1 inventory, then reinvests a % of monthly profit into more stock for the next month | M2: 12-Month Scaling Roadmap Each scenario starts with Month 1 inventory, then reinvests a % of monthly profit into more stock for the next month
A4: Bad CPA Scenario | B4: Bad CPA Scenario | C4: Bad CPA Scenario | D4: Bad CPA Scenario | E4: Bad CPA Scenario | F4: Bad CPA Scenario | G4: Bad CPA Scenario | H4: Bad CPA Scenario | I4: Bad CPA Scenario | J4: Bad CPA Scenario | K4: Bad CPA Scenario | L4: Bad CPA Scenario | M4: Bad CPA Scenario
A5: Metric | B5: M1 | C5: M2 | D5: M3 | E5: M4 | F5: M5 | G5: M6 | H5: M7 | I5: M8 | J5: M9 | K5: M10 | L5: M11 | M5: M12
A6: Order units | B6: =Inputs!$B$8 -> 75 | C6: =MIN(FLOOR(B6*(1+Inputs!$B$13),1),B6+B15) -> 75 | D6: =MIN(FLOOR(C6*(1+Inputs!$B$13),1),C6+C15) -> 75 | E6: =MIN(FLOOR(D6*(1+Inputs!$B$13),1),D6+D15) -> 75 | F6: =MIN(FLOOR(E6*(1+Inputs!$B$13),1),E6+E15) -> 75 | G6: =MIN(FLOOR(F6*(1+Inputs!$B$13),1),F6+F15) -> 75 | H6: =MIN(FLOOR(G6*(1+Inputs!$B$13),1),G6+G15) -> 75 | I6: =MIN(FLOOR(H6*(1+Inputs!$B$13),1),H6+H15) -> 75 | J6: =MIN(FLOOR(I6*(1+Inputs!$B$13),1),I6+I15) -> 75 | ... M6: =MIN(FLOOR(L6*(1+Inputs!$B$13),1),L6+L15) -> 75
A7: Units sold | B7: =B6*Inputs!$B$10 -> 75 | C7: =C6*Inputs!$B$10 -> 75 | D7: =D6*Inputs!$B$10 -> 75 | E7: =E6*Inputs!$B$10 -> 75 | F7: =F6*Inputs!$B$10 -> 75 | G7: =G6*Inputs!$B$10 -> 75 | H7: =H6*Inputs!$B$10 -> 75 | I7: =I6*Inputs!$B$10 -> 75 | ... M7: =M6*Inputs!$B$10 -> 75
A8: Net revenue | B8: =B7*Inputs!$B$7*(1-Inputs!$B$11) -> 21825 | C8: =C7*Inputs!$B$7*(1-Inputs!$B$11) -> 21825 | D8: =D7*Inputs!$B$7*(1-Inputs!$B$11) -> 21825 | E8: =E7*Inputs!$B$7*(1-Inputs!$B$11) -> 21825 | F8: =F7*Inputs!$B$7*(1-Inputs!$B$11) -> 21825 | G8: =G7*Inputs!$B$7*(1-Inputs!$B$11) -> 21825 | H8: =H7*Inputs!$B$7*(1-Inputs!$B$11) -> 21825 | I8: =I7*Inputs!$B$7*(1-Inputs!$B$11) -> 21825 | ... M8: =M7*Inputs!$B$7*(1-Inputs!$B$11) -> 21825
A9: Variable cost before ads | B9: =B7*Inputs!$B$24 -> 15000 | C9: =C7*Inputs!$B$24 -> 15000 | D9: =D7*Inputs!$B$24 -> 15000 | E9: =E7*Inputs!$B$24 -> 15000 | F9: =F7*Inputs!$B$24 -> 15000 | G9: =G7*Inputs!$B$24 -> 15000 | H9: =H7*Inputs!$B$24 -> 15000 | I9: =I7*Inputs!$B$24 -> 15000 | ... M9: =M7*Inputs!$B$24 -> 15000
A10: Meta ad spend | B10: =B7*Inputs!$C$29 -> 9450 | C10: =C7*Inputs!$C$29 -> 9450 | D10: =D7*Inputs!$C$29 -> 9450 | E10: =E7*Inputs!$C$29 -> 9450 | F10: =F7*Inputs!$C$29 -> 9450 | G10: =G7*Inputs!$C$29 -> 9450 | H10: =H7*Inputs!$C$29 -> 9450 | I10: =I7*Inputs!$C$29 -> 9450 | ... M10: =M7*Inputs!$C$29 -> 9450
A11: Fixed overhead | B11: =Inputs!$B$12 -> 0 | C11: =Inputs!$B$12 -> 0 | D11: =Inputs!$B$12 -> 0 | E11: =Inputs!$B$12 -> 0 | F11: =Inputs!$B$12 -> 0 | G11: =Inputs!$B$12 -> 0 | H11: =Inputs!$B$12 -> 0 | I11: =Inputs!$B$12 -> 0 | ... M11: =Inputs!$B$12 -> 0
A12: Net profit | B12: =B8-B9-B10-B11 -> -2625 | C12: =C8-C9-C10-C11 -> -2625 | D12: =D8-D9-D10-D11 -> -2625 | E12: =E8-E9-E10-E11 -> -2625 | F12: =F8-F9-F10-F11 -> -2625 | G12: =G8-G9-G10-G11 -> -2625 | H12: =H8-H9-H10-H11 -> -2625 | I12: =I8-I9-I10-I11 -> -2625 | ... M12: =M8-M9-M10-M11 -> -2625
A13: Cash kept | B13: =MAX(0,B12*(1-Inputs!$D$29)) -> 0 | C13: =MAX(0,C12*(1-Inputs!$D$29)) -> 0 | D13: =MAX(0,D12*(1-Inputs!$D$29)) -> 0 | E13: =MAX(0,E12*(1-Inputs!$D$29)) -> 0 | F13: =MAX(0,F12*(1-Inputs!$D$29)) -> 0 | G13: =MAX(0,G12*(1-Inputs!$D$29)) -> 0 | H13: =MAX(0,H12*(1-Inputs!$D$29)) -> 0 | I13: =MAX(0,I12*(1-Inputs!$D$29)) -> 0 | ... M13: =MAX(0,M12*(1-Inputs!$D$29)) -> 0
A14: Profit reinvested | B14: =MAX(0,B12*Inputs!$D$29) -> 0 | C14: =MAX(0,C12*Inputs!$D$29) -> 0 | D14: =MAX(0,D12*Inputs!$D$29) -> 0 | E14: =MAX(0,E12*Inputs!$D$29) -> 0 | F14: =MAX(0,F12*Inputs!$D$29) -> 0 | G14: =MAX(0,G12*Inputs!$D$29) -> 0 | H14: =MAX(0,H12*Inputs!$D$29) -> 0 | I14: =MAX(0,I12*Inputs!$D$29) -> 0 | ... M14: =MAX(0,M12*Inputs!$D$29) -> 0
A15: Added units next month | B15: =FLOOR(B14/Inputs!$B$16,1) -> 0 | C15: =FLOOR(C14/Inputs!$B$16,1) -> 0 | D15: =FLOOR(D14/Inputs!$B$16,1) -> 0 | E15: =FLOOR(E14/Inputs!$B$16,1) -> 0 | F15: =FLOOR(F14/Inputs!$B$16,1) -> 0 | G15: =FLOOR(G14/Inputs!$B$16,1) -> 0 | H15: =FLOOR(H14/Inputs!$B$16,1) -> 0 | I15: =FLOOR(I14/Inputs!$B$16,1) -> 0 | ... M15: =FLOOR(M14/Inputs!$B$16,1) -> 0
A16: Cumulative net profit | B16: =B12 -> -2625 | C16: =B16+C12 -> -5250 | D16: =C16+D12 -> -7875 | E16: =D16+E12 -> -10500 | F16: =E16+F12 -> -13125 | G16: =F16+G12 -> -15750 | H16: =G16+H12 -> -18375 | I16: =H16+I12 -> -21000 | J16: =I16+J12 -> -23625 | ... M16: =L16+M12 -> -31500
A17: ROAS | B17: =B8/B10 -> 2.3095238 | C17: =C8/C10 -> 2.3095238 | D17: =D8/D10 -> 2.3095238 | E17: =E8/E10 -> 2.3095238 | F17: =F8/F10 -> 2.3095238 | G17: =G8/G10 -> 2.3095238 | H17: =H8/H10 -> 2.3095238 | I17: =I8/I10 -> 2.3095238 | ... M17: =M8/M10 -> 2.3095238
A18: MER | B18: =B10/B8 -> 0.43298969 | C18: =C10/C8 -> 0.43298969 | D18: =D10/D8 -> 0.43298969 | E18: =E10/E8 -> 0.43298969 | F18: =F10/F8 -> 0.43298969 | G18: =G10/G8 -> 0.43298969 | H18: =H10/H8 -> 0.43298969 | I18: =I10/I8 -> 0.43298969 | ... M18: =M10/M8 -> 0.43298969
A19: CPA cushion / unit | B19: =Inputs!$B$25-Inputs!$C$29 -> -26 | C19: =Inputs!$B$25-Inputs!$C$29 -> -26 | D19: =Inputs!$B$25-Inputs!$C$29 -> -26 | E19: =Inputs!$B$25-Inputs!$C$29 -> -26 | F19: =Inputs!$B$25-Inputs!$C$29 -> -26 | G19: =Inputs!$B$25-Inputs!$C$29 -> -26 | H19: =Inputs!$B$25-Inputs!$C$29 -> -26 | I19: =Inputs!$B$25-Inputs!$C$29 -> -26 | ... M19: =Inputs!$B$25-Inputs!$C$29 -> -26
A20: Scenario status | B20: =IF(B12>0,"Profitable","Loss / review") -> Loss / review | C20: =IF(C12>0,"Profitable","Loss / review") -> Loss / review | D20: =IF(D12>0,"Profitable","Loss / review") -> Loss / review | E20: =IF(E12>0,"Profitable","Loss / review") -> Loss / review | F20: =IF(F12>0,"Profitable","Loss / review") -> Loss / review | G20: =IF(G12>0,"Profitable","Loss / review") -> Loss / review | H20: =IF(H12>0,"Profitable","Loss / review") -> Loss / review | I20: =IF(I12>0,"Profitable","Loss / review") -> Loss / review | ... M20: =IF(M12>0,"Profitable","Loss / review") -> Loss / review
A21: Reinvest % | B21: =Inputs!$D$29 -> 0.3 | C21: =Inputs!$D$29 -> 0.3 | D21: =Inputs!$D$29 -> 0.3 | E21: =Inputs!$D$29 -> 0.3 | F21: =Inputs!$D$29 -> 0.3 | G21: =Inputs!$D$29 -> 0.3 | H21: =Inputs!$D$29 -> 0.3 | I21: =Inputs!$D$29 -> 0.3 | ... M21: =Inputs!$D$29 -> 0.3
A23: Base CPA Scenario | B23: Base CPA Scenario | C23: Base CPA Scenario | D23: Base CPA Scenario | E23: Base CPA Scenario | F23: Base CPA Scenario | G23: Base CPA Scenario | H23: Base CPA Scenario | I23: Base CPA Scenario | J23: Base CPA Scenario | K23: Base CPA Scenario | L23: Base CPA Scenario | M23: Base CPA Scenario
A24: Metric | B24: M1 | C24: M2 | D24: M3 | E24: M4 | F24: M5 | G24: M6 | H24: M7 | I24: M8 | J24: M9 | K24: M10 | L24: M11 | M24: M12
A25: Order units | B25: =Inputs!$B$8 -> 75 | C25: =MIN(FLOOR(B25*(1+Inputs!$B$13),1),B25+B34) -> 75 | D25: =MIN(FLOOR(C25*(1+Inputs!$B$13),1),C25+C34) -> 75 | E25: =MIN(FLOOR(D25*(1+Inputs!$B$13),1),D25+D34) -> 75 | F25: =MIN(FLOOR(E25*(1+Inputs!$B$13),1),E25+E34) -> 75 | G25: =MIN(FLOOR(F25*(1+Inputs!$B$13),1),F25+F34) -> 75 | H25: =MIN(FLOOR(G25*(1+Inputs!$B$13),1),G25+G34) -> 75 | I25: =MIN(FLOOR(H25*(1+Inputs!$B$13),1),H25+H34) -> 75 | J25: =MIN(FLOOR(I25*(1+Inputs!$B$13),1),I25+I34) -> 75 | ... M25: =MIN(FLOOR(L25*(1+Inputs!$B$13),1),L25+L34) -> 75
A26: Units sold | B26: =B25*Inputs!$B$10 -> 75 | C26: =C25*Inputs!$B$10 -> 75 | D26: =D25*Inputs!$B$10 -> 75 | E26: =E25*Inputs!$B$10 -> 75 | F26: =F25*Inputs!$B$10 -> 75 | G26: =G25*Inputs!$B$10 -> 75 | H26: =H25*Inputs!$B$10 -> 75 | I26: =I25*Inputs!$B$10 -> 75 | ... M26: =M25*Inputs!$B$10 -> 75
A27: Net revenue | B27: =B26*Inputs!$B$7*(1-Inputs!$B$11) -> 21825 | C27: =C26*Inputs!$B$7*(1-Inputs!$B$11) -> 21825 | D27: =D26*Inputs!$B$7*(1-Inputs!$B$11) -> 21825 | E27: =E26*Inputs!$B$7*(1-Inputs!$B$11) -> 21825 | F27: =F26*Inputs!$B$7*(1-Inputs!$B$11) -> 21825 | G27: =G26*Inputs!$B$7*(1-Inputs!$B$11) -> 21825 | H27: =H26*Inputs!$B$7*(1-Inputs!$B$11) -> 21825 | I27: =I26*Inputs!$B$7*(1-Inputs!$B$11) -> 21825 | ... M27: =M26*Inputs!$B$7*(1-Inputs!$B$11) -> 21825
A28: Variable cost before ads | B28: =B26*Inputs!$B$24 -> 15000 | C28: =C26*Inputs!$B$24 -> 15000 | D28: =D26*Inputs!$B$24 -> 15000 | E28: =E26*Inputs!$B$24 -> 15000 | F28: =F26*Inputs!$B$24 -> 15000 | G28: =G26*Inputs!$B$24 -> 15000 | H28: =H26*Inputs!$B$24 -> 15000 | I28: =I26*Inputs!$B$24 -> 15000 | ... M28: =M26*Inputs!$B$24 -> 15000
A29: Meta ad spend | B29: =B26*Inputs!$C$30 -> 7200 | C29: =C26*Inputs!$C$30 -> 7200 | D29: =D26*Inputs!$C$30 -> 7200 | E29: =E26*Inputs!$C$30 -> 7200 | F29: =F26*Inputs!$C$30 -> 7200 | G29: =G26*Inputs!$C$30 -> 7200 | H29: =H26*Inputs!$C$30 -> 7200 | I29: =I26*Inputs!$C$30 -> 7200 | ... M29: =M26*Inputs!$C$30 -> 7200
A30: Fixed overhead | B30: =Inputs!$B$12 -> 0 | C30: =Inputs!$B$12 -> 0 | D30: =Inputs!$B$12 -> 0 | E30: =Inputs!$B$12 -> 0 | F30: =Inputs!$B$12 -> 0 | G30: =Inputs!$B$12 -> 0 | H30: =Inputs!$B$12 -> 0 | I30: =Inputs!$B$12 -> 0 | ... M30: =Inputs!$B$12 -> 0
A31: Net profit | B31: =B27-B28-B29-B30 -> -375 | C31: =C27-C28-C29-C30 -> -375 | D31: =D27-D28-D29-D30 -> -375 | E31: =E27-E28-E29-E30 -> -375 | F31: =F27-F28-F29-F30 -> -375 | G31: =G27-G28-G29-G30 -> -375 | H31: =H27-H28-H29-H30 -> -375 | I31: =I27-I28-I29-I30 -> -375 | ... M31: =M27-M28-M29-M30 -> -375
A32: Cash kept | B32: =MAX(0,B31*(1-Inputs!$D$30)) -> 0 | C32: =MAX(0,C31*(1-Inputs!$D$30)) -> 0 | D32: =MAX(0,D31*(1-Inputs!$D$30)) -> 0 | E32: =MAX(0,E31*(1-Inputs!$D$30)) -> 0 | F32: =MAX(0,F31*(1-Inputs!$D$30)) -> 0 | G32: =MAX(0,G31*(1-Inputs!$D$30)) -> 0 | H32: =MAX(0,H31*(1-Inputs!$D$30)) -> 0 | I32: =MAX(0,I31*(1-Inputs!$D$30)) -> 0 | ... M32: =MAX(0,M31*(1-Inputs!$D$30)) -> 0
A33: Profit reinvested | B33: =MAX(0,B31*Inputs!$D$30) -> 0 | C33: =MAX(0,C31*Inputs!$D$30) -> 0 | D33: =MAX(0,D31*Inputs!$D$30) -> 0 | E33: =MAX(0,E31*Inputs!$D$30) -> 0 | F33: =MAX(0,F31*Inputs!$D$30) -> 0 | G33: =MAX(0,G31*Inputs!$D$30) -> 0 | H33: =MAX(0,H31*Inputs!$D$30) -> 0 | I33: =MAX(0,I31*Inputs!$D$30) -> 0 | ... M33: =MAX(0,M31*Inputs!$D$30) -> 0
A34: Added units next month | B34: =FLOOR(B33/Inputs!$B$16,1) -> 0 | C34: =FLOOR(C33/Inputs!$B$16,1) -> 0 | D34: =FLOOR(D33/Inputs!$B$16,1) -> 0 | E34: =FLOOR(E33/Inputs!$B$16,1) -> 0 | F34: =FLOOR(F33/Inputs!$B$16,1) -> 0 | G34: =FLOOR(G33/Inputs!$B$16,1) -> 0 | H34: =FLOOR(H33/Inputs!$B$16,1) -> 0 | I34: =FLOOR(I33/Inputs!$B$16,1) -> 0 | ... M34: =FLOOR(M33/Inputs!$B$16,1) -> 0
A35: Cumulative net profit | B35: =B31 -> -375 | C35: =B35+C31 -> -750 | D35: =C35+D31 -> -1125 | E35: =D35+E31 -> -1500 | F35: =E35+F31 -> -1875 | G35: =F35+G31 -> -2250 | H35: =G35+H31 -> -2625 | I35: =H35+I31 -> -3000 | J35: =I35+J31 -> -3375 | ... M35: =L35+M31 -> -4500
A36: ROAS | B36: =B27/B29 -> 3.03125 | C36: =C27/C29 -> 3.03125 | D36: =D27/D29 -> 3.03125 | E36: =E27/E29 -> 3.03125 | F36: =F27/F29 -> 3.03125 | G36: =G27/G29 -> 3.03125 | H36: =H27/H29 -> 3.03125 | I36: =I27/I29 -> 3.03125 | ... M36: =M27/M29 -> 3.03125
A37: MER | B37: =B29/B27 -> 0.32989691 | C37: =C29/C27 -> 0.32989691 | D37: =D29/D27 -> 0.32989691 | E37: =E29/E27 -> 0.32989691 | F37: =F29/F27 -> 0.32989691 | G37: =G29/G27 -> 0.32989691 | H37: =H29/H27 -> 0.32989691 | I37: =I29/I27 -> 0.32989691 | ... M37: =M29/M27 -> 0.32989691
A38: CPA cushion / unit | B38: =Inputs!$B$25-Inputs!$C$30 -> 4 | C38: =Inputs!$B$25-Inputs!$C$30 -> 4 | D38: =Inputs!$B$25-Inputs!$C$30 -> 4 | E38: =Inputs!$B$25-Inputs!$C$30 -> 4 | F38: =Inputs!$B$25-Inputs!$C$30 -> 4 | G38: =Inputs!$B$25-Inputs!$C$30 -> 4 | H38: =Inputs!$B$25-Inputs!$C$30 -> 4 | I38: =Inputs!$B$25-Inputs!$C$30 -> 4 | ... M38: =Inputs!$B$25-Inputs!$C$30 -> 4
A39: Scenario status | B39: =IF(B31>0,"Profitable","Loss / review") -> Loss / review | C39: =IF(C31>0,"Profitable","Loss / review") -> Loss / review | D39: =IF(D31>0,"Profitable","Loss / review") -> Loss / review | E39: =IF(E31>0,"Profitable","Loss / review") -> Loss / review | F39: =IF(F31>0,"Profitable","Loss / review") -> Loss / review | G39: =IF(G31>0,"Profitable","Loss / review") -> Loss / review | H39: =IF(H31>0,"Profitable","Loss / review") -> Loss / review | I39: =IF(I31>0,"Profitable","Loss / review") -> Loss / review | ... M39: =IF(M31>0,"Profitable","Loss / review") -> Loss / review
A40: Reinvest % | B40: =Inputs!$D$30 -> 0.5 | C40: =Inputs!$D$30 -> 0.5 | D40: =Inputs!$D$30 -> 0.5 | E40: =Inputs!$D$30 -> 0.5 | F40: =Inputs!$D$30 -> 0.5 | G40: =Inputs!$D$30 -> 0.5 | H40: =Inputs!$D$30 -> 0.5 | I40: =Inputs!$D$30 -> 0.5 | ... M40: =Inputs!$D$30 -> 0.5
A42: Good CPA Scenario | B42: Good CPA Scenario | C42: Good CPA Scenario | D42: Good CPA Scenario | E42: Good CPA Scenario | F42: Good CPA Scenario | G42: Good CPA Scenario | H42: Good CPA Scenario | I42: Good CPA Scenario | J42: Good CPA Scenario | K42: Good CPA Scenario | L42: Good CPA Scenario | M42: Good CPA Scenario
A43: Metric | B43: M1 | C43: M2 | D43: M3 | E43: M4 | F43: M5 | G43: M6 | H43: M7 | I43: M8 | J43: M9 | K43: M10 | L43: M11 | M43: M12
...

Sheet Scenario Matrix
A1: Scenario Matrix Compare CPA case x reinvestment rate across the same 12-month model | B1: Scenario Matrix Compare CPA case x reinvestment rate across the same 12-month model | C1: Scenario Matrix Compare CPA case x reinvestment rate across the same 12-month model | D1: Scenario Matrix Compare CPA case x reinvestment rate across the same 12-month model | E1: Scenario Matrix Compare CPA case x reinvestment rate across the same 12-month model | F1: Scenario Matrix Compare CPA case x reinvestment rate across the same 12-month model | G1: Scenario Matrix Compare CPA case x reinvestment rate across the same 12-month model | H1: Scenario Matrix Compare CPA case x reinvestment rate across the same 12-month model | I1: Scenario Matrix Compare CPA case x reinvestment rate across the same 12-month model | J1: Scenario Matrix Compare CPA case x reinvestment rate across the same 12-month model | K1: Scenario Matrix Compare CPA case x reinvestment rate across the same 12-month model | L1: Scenario Matrix Compare CPA case x reinvestment rate across the same 12-month model | M1: Scenario Matrix Compare CPA case x reinvestment rate across the same 12-month model | N1: Scenario Matrix Compare CPA case x reinvestment rate across the same 12-month model | O1: Scenario Matrix Compare CPA case x reinvestment rate across the same 12-month model
A2: Scenario Matrix Compare CPA case x reinvestment rate across the same 12-month model | B2: Scenario Matrix Compare CPA case x reinvestment rate across the same 12-month model | C2: Scenario Matrix Compare CPA case x reinvestment rate across the same 12-month model | D2: Scenario Matrix Compare CPA case x reinvestment rate across the same 12-month model | E2: Scenario Matrix Compare CPA case x reinvestment rate across the same 12-month model | F2: Scenario Matrix Compare CPA case x reinvestment rate across the same 12-month model | G2: Scenario Matrix Compare CPA case x reinvestment rate across the same 12-month model | H2: Scenario Matrix Compare CPA case x reinvestment rate across the same 12-month model | I2: Scenario Matrix Compare CPA case x reinvestment rate across the same 12-month model | J2: Scenario Matrix Compare CPA case x reinvestment rate across the same 12-month model | K2: Scenario Matrix Compare CPA case x reinvestment rate across the same 12-month model | L2: Scenario Matrix Compare CPA case x reinvestment rate across the same 12-month model | M2: Scenario Matrix Compare CPA case x reinvestment rate across the same 12-month model | N2: Scenario Matrix Compare CPA case x reinvestment rate across the same 12-month model | O2: Scenario Matrix Compare CPA case x reinvestment rate across the same 12-month model
A4: Summary of 9 Scaling Paths | B4: Summary of 9 Scaling Paths | C4: Summary of 9 Scaling Paths | D4: Summary of 9 Scaling Paths | E4: Summary of 9 Scaling Paths | F4: Summary of 9 Scaling Paths | G4: Summary of 9 Scaling Paths | H4: Summary of 9 Scaling Paths | I4: Summary of 9 Scaling Paths | J4: Summary of 9 Scaling Paths | K4: Summary of 9 Scaling Paths | L4: Summary of 9 Scaling Paths | M4: Summary of 9 Scaling Paths | N4: Summary of 9 Scaling Paths | O4: Summary of 9 Scaling Paths | P4: Helper: Units by Month | Q4: Helper: Units by Month | R4: Helper: Units by Month | S4: Helper: Units by Month | T4: Helper: Units by Month | U4: Helper: Units by Month | V4: Helper: Units by Month | W4: Helper: Units by Month | X4: Helper: Units by Month | Y4: Helper: Units by Month | Z4: Helper: Units by Month | AA4: Helper: Units by Month | AB4: Helper: Net Profit by Month | AC4: Helper: Net Profit by Month | AD4: Helper: Net Profit by Month | AE4: Helper: Net Profit by Month | AF4: Helper: Net Profit by Month | AG4: Helper: Net Profit by Month | AH4: Helper: Net Profit by Month | AI4: Helper: Net Profit by Month | AJ4: Helper: Net Profit by Month | AK4: Helper: Net Profit by Month | AL4: Helper: Net Profit by Month | AM4: Helper: Net Profit by Month | AN4: Helper: Cash Kept by Month | AO4: Helper: Cash Kept by Month | AP4: Helper: Cash Kept by Month | AQ4: Helper: Cash Kept by Month | AR4: Helper: Cash Kept by Month | AS4: Helper: Cash Kept by Month | AT4: Helper: Cash Kept by Month | AU4: Helper: Cash Kept by Month | AV4: Helper: Cash Kept by Month | AW4: Helper: Cash Kept by Month | AX4: Helper: Cash Kept by Month | AY4: Helper: Cash Kept by Month | AZ4: Helper: Reinvested by Month | BA4: Helper: Reinvested by Month | BB4: Helper: Reinvested by Month | BC4: Helper: Reinvested by Month | BD4: Helper: Reinvested by Month | BE4: Helper: Reinvested by Month | BF4: Helper: Reinvested by Month | BG4: Helper: Reinvested by Month | BH4: Helper: Reinvested by Month | BI4: Helper: Reinvested by Month | BJ4: Helper: Reinvested by Month | BK4: Helper: Reinvested by Month
A5: Combo | B5: CPA case | C5: CPA | D5: Reinvest % | E5: M1 units | F5: M6 units | G5: M12 units | H5: M12 net profit | I5: Cumulative net profit | J5: Cash kept | K5: Reinvested total | L5: M12 ad spend | M5: ROAS | N5: MER | O5: Status | P5: M1 Units | Q5: M2 Units | R5: M3 Units | S5: M4 Units | T5: M5 Units | U5: M6 Units | V5: M7 Units | W5: M8 Units | X5: M9 Units | Y5: M10 Units | Z5: M11 Units | AA5: M12 Units | AB5: M1 Profit | AC5: M2 Profit | AD5: M3 Profit | AE5: M4 Profit | AF5: M5 Profit | AG5: M6 Profit | AH5: M7 Profit | AI5: M8 Profit | AJ5: M9 Profit | AK5: M10 Profit | AL5: M11 Profit | AM5: M12 Profit | AN5: M1 Cash | AO5: M2 Cash | AP5: M3 Cash | AQ5: M4 Cash | AR5: M5 Cash | AS5: M6 Cash | AT5: M7 Cash | AU5: M8 Cash | AV5: M9 Cash | AW5: M10 Cash | AX5: M11 Cash | AY5: M12 Cash | AZ5: M1 Reinvest | BA5: M2 Reinvest | BB5: M3 Reinvest | BC5: M4 Reinvest | BD5: M5 Reinvest | BE5: M6 Reinvest | BF5: M7 Reinvest | BG5: M8 Reinvest | BH5: M9 Reinvest | BI5: M10 Reinvest | BJ5: M11 Reinvest | BK5: M12 Reinvest
A6: Bad / 30% | B6: Bad CPA | C6: =INDEX(Inputs!$C$29:$C$31,MATCH(B6,Inputs!$A$29:$A$31,0)) -> 126 | D6: 0.3 | E6: =P6 -> 75 | F6: =U6 -> 75 | G6: =AA6 -> 75 | H6: =AM6 -> -2625 | I6: =SUM(AB6:AM6) -> -31500 | J6: =SUM(AN6:AY6) -> 0 | K6: =SUM(AZ6:BK6) -> 0 | L6: =AA6*$C6 -> 9450 | M6: =Inputs!$B$7/$C6 -> 2.3809524 | N6: =$C6/Inputs!$B$7 -> 0.42 | O6: =IF(I6>0,"OK","Loss / review") -> Loss / review | P6: =Inputs!$B$8 -> 75 | Q6: =MIN(FLOOR(P6*(1+Inputs!$B$13),1),P6+FLOOR(MAX(0,AZ6)/Inputs!$B$16,1)) -> 75 | R6: =MIN(FLOOR(Q6*(1+Inputs!$B$13),1),Q6+FLOOR(MAX(0,BA6)/Inputs!$B$16,1)) -> 75 | S6: =MIN(FLOOR(R6*(1+Inputs!$B$13),1),R6+FLOOR(MAX(0,BB6)/Inputs!$B$16,1)) -> 75 | T6: =MIN(FLOOR(S6*(1+Inputs!$B$13),1),S6+FLOOR(MAX(0,BC6)/Inputs!$B$16,1)) -> 75 | U6: =MIN(FLOOR(T6*(1+Inputs!$B$13),1),T6+FLOOR(MAX(0,BD6)/Inputs!$B$16,1)) -> 75 | V6: =MIN(FLOOR(U6*(1+Inputs!$B$13),1),U6+FLOOR(MAX(0,BE6)/Inputs!$B$16,1)) -> 75 | W6: =MIN(FLOOR(V6*(1+Inputs!$B$13),1),V6+FLOOR(MAX(0,BF6)/Inputs!$B$16,1)) -> 75 | X6: =MIN(FLOOR(W6*(1+Inputs!$B$13),1),W6+FLOOR(MAX(0,BG6)/Inputs!$B$16,1)) -> 75 | ... AA6: =MIN(FLOOR(Z6*(1+Inputs!$B$13),1),Z6+FLOOR(MAX(0,BJ6)/Inputs!$B$16,1)) -> 75 | AB6: =P6*Inputs!$B$10*Inputs!$B$7*(1-Inputs!$B$11)-P6*Inputs!$B$10*Inputs!$B$24-P6*Inputs!$B$10*$C6-Inputs!$B$12 -> -2625 | AC6: =Q6*Inputs!$B$10*Inputs!$B$7*(1-Inputs!$B$11)-Q6*Inputs!$B$10*Inputs!$B$24-Q6*Inputs!$B$10*$C6-Inputs!$B$12 -> -2625 | AD6: =R6*Inputs!$B$10*Inputs!$B$7*(1-Inputs!$B$11)-R6*Inputs!$B$10*Inputs!$B$24-R6*Inputs!$B$10*$C6-Inputs!$B$12 -> -2625 | AE6: =S6*Inputs!$B$10*Inputs!$B$7*(1-Inputs!$B$11)-S6*Inputs!$B$10*Inputs!$B$24-S6*Inputs!$B$10*$C6-Inputs!$B$12 -> -2625 | AF6: =T6*Inputs!$B$10*Inputs!$B$7*(1-Inputs!$B$11)-T6*Inputs!$B$10*Inputs!$B$24-T6*Inputs!$B$10*$C6-Inputs!$B$12 -> -2625 | AG6: =U6*Inputs!$B$10*Inputs!$B$7*(1-Inputs!$B$11)-U6*Inputs!$B$10*Inputs!$B$24-U6*Inputs!$B$10*$C6-Inputs!$B$12 -> -2625 | AH6: =V6*Inputs!$B$10*Inputs!$B$7*(1-Inputs!$B$11)-V6*Inputs!$B$10*Inputs!$B$24-V6*Inputs!$B$10*$C6-Inputs!$B$12 -> -2625 | AI6: =W6*Inputs!$B$10*Inputs!$B$7*(1-Inputs!$B$11)-W6*Inputs!$B$10*Inputs!$B$24-W6*Inputs!$B$10*$C6-Inputs!$B$12 -> -2625 | ... AM6: =AA6*Inputs!$B$10*Inputs!$B$7*(1-Inputs!$B$11)-AA6*Inputs!$B$10*Inputs!$B$24-AA6*Inputs!$B$10*$C6-Inputs!$B$12 -> -2625 | AN6: =MAX(0,AB6*(1-$D6)) -> 0 | AO6: =MAX(0,AC6*(1-$D6)) -> 0 | AP6: =MAX(0,AD6*(1-$D6)) -> 0 | AQ6: =MAX(0,AE6*(1-$D6)) -> 0 | AR6: =MAX(0,AF6*(1-$D6)) -> 0 | AS6: =MAX(0,AG6*(1-$D6)) -> 0 | AT6: =MAX(0,AH6*(1-$D6)) -> 0 | AU6: =MAX(0,AI6*(1-$D6)) -> 0 | ... AY6: =MAX(0,AM6*(1-$D6)) -> 0 | AZ6: =MAX(0,AB6*$D6) -> 0 | BA6: =MAX(0,AC6*$D6) -> 0 | BB6: =MAX(0,AD6*$D6) -> 0 | BC6: =MAX(0,AE6*$D6) -> 0 | BD6: =MAX(0,AF6*$D6) -> 0 | BE6: =MAX(0,AG6*$D6) -> 0 | BF6: =MAX(0,AH6*$D6) -> 0 | BG6: =MAX(0,AI6*$D6) -> 0 | ... BK6: =MAX(0,AM6*$D6) -> 0
A7: Bad / 50% | B7: Bad CPA | C7: =INDEX(Inputs!$C$29:$C$31,MATCH(B7,Inputs!$A$29:$A$31,0)) -> 126 | D7: 0.5 | E7: =P7 -> 75 | F7: =U7 -> 75 | G7: =AA7 -> 75 | H7: =AM7 -> -2625 | I7: =SUM(AB7:AM7) -> -31500 | J7: =SUM(AN7:AY7) -> 0 | K7: =SUM(AZ7:BK7) -> 0 | L7: =AA7*$C7 -> 9450 | M7: =Inputs!$B$7/$C7 -> 2.3809524 | N7: =$C7/Inputs!$B$7 -> 0.42 | O7: =IF(I7>0,"OK","Loss / review") -> Loss / review | P7: =Inputs!$B$8 -> 75 | Q7: =MIN(FLOOR(P7*(1+Inputs!$B$13),1),P7+FLOOR(MAX(0,AZ7)/Inputs!$B$16,1)) -> 75 | R7: =MIN(FLOOR(Q7*(1+Inputs!$B$13),1),Q7+FLOOR(MAX(0,BA7)/Inputs!$B$16,1)) -> 75 | S7: =MIN(FLOOR(R7*(1+Inputs!$B$13),1),R7+FLOOR(MAX(0,BB7)/Inputs!$B$16,1)) -> 75 | T7: =MIN(FLOOR(S7*(1+Inputs!$B$13),1),S7+FLOOR(MAX(0,BC7)/Inputs!$B$16,1)) -> 75 | U7: =MIN(FLOOR(T7*(1+Inputs!$B$13),1),T7+FLOOR(MAX(0,BD7)/Inputs!$B$16,1)) -> 75 | V7: =MIN(FLOOR(U7*(1+Inputs!$B$13),1),U7+FLOOR(MAX(0,BE7)/Inputs!$B$16,1)) -> 75 | W7: =MIN(FLOOR(V7*(1+Inputs!$B$13),1),V7+FLOOR(MAX(0,BF7)/Inputs!$B$16,1)) -> 75 | X7: =MIN(FLOOR(W7*(1+Inputs!$B$13),1),W7+FLOOR(MAX(0,BG7)/Inputs!$B$16,1)) -> 75 | ... AA7: =MIN(FLOOR(Z7*(1+Inputs!$B$13),1),Z7+FLOOR(MAX(0,BJ7)/Inputs!$B$16,1)) -> 75 | AB7: =P7*Inputs!$B$10*Inputs!$B$7*(1-Inputs!$B$11)-P7*Inputs!$B$10*Inputs!$B$24-P7*Inputs!$B$10*$C7-Inputs!$B$12 -> -2625 | AC7: =Q7*Inputs!$B$10*Inputs!$B$7*(1-Inputs!$B$11)-Q7*Inputs!$B$10*Inputs!$B$24-Q7*Inputs!$B$10*$C7-Inputs!$B$12 -> -2625 | AD7: =R7*Inputs!$B$10*Inputs!$B$7*(1-Inputs!$B$11)-R7*Inputs!$B$10*Inputs!$B$24-R7*Inputs!$B$10*$C7-Inputs!$B$12 -> -2625 | AE7: =S7*Inputs!$B$10*Inputs!$B$7*(1-Inputs!$B$11)-S7*Inputs!$B$10*Inputs!$B$24-S7*Inputs!$B$10*$C7-Inputs!$B$12 -> -2625 | AF7: =T7*Inputs!$B$10*Inputs!$B$7*(1-Inputs!$B$11)-T7*Inputs!$B$10*Inputs!$B$24-T7*Inputs!$B$10*$C7-Inputs!$B$12 -> -2625 | AG7: =U7*Inputs!$B$10*Inputs!$B$7*(1-Inputs!$B$11)-U7*Inputs!$B$10*Inputs!$B$24-U7*Inputs!$B$10*$C7-Inputs!$B$12 -> -2625 | AH7: =V7*Inputs!$B$10*Inputs!$B$7*(1-Inputs!$B$11)-V7*Inputs!$B$10*Inputs!$B$24-V7*Inputs!$B$10*$C7-Inputs!$B$12 -> -2625 | AI7: =W7*Inputs!$B$10*Inputs!$B$7*(1-Inputs!$B$11)-W7*Inputs!$B$10*Inputs!$B$24-W7*Inputs!$B$10*$C7-Inputs!$B$12 -> -2625 | ... AM7: =AA7*Inputs!$B$10*Inputs!$B$7*(1-Inputs!$B$11)-AA7*Inputs!$B$10*Inputs!$B$24-AA7*Inputs!$B$10*$C7-Inputs!$B$12 -> -2625 | AN7: =MAX(0,AB7*(1-$D7)) -> 0 | AO7: =MAX(0,AC7*(1-$D7)) -> 0 | AP7: =MAX(0,AD7*(1-$D7)) -> 0 | AQ7: =MAX(0,AE7*(1-$D7)) -> 0 | AR7: =MAX(0,AF7*(1-$D7)) -> 0 | AS7: =MAX(0,AG7*(1-$D7)) -> 0 | AT7: =MAX(0,AH7*(1-$D7)) -> 0 | AU7: =MAX(0,AI7*(1-$D7)) -> 0 | ... AY7: =MAX(0,AM7*(1-$D7)) -> 0 | AZ7: =MAX(0,AB7*$D7) -> 0 | BA7: =MAX(0,AC7*$D7) -> 0 | BB7: =MAX(0,AD7*$D7) -> 0 | BC7: =MAX(0,AE7*$D7) -> 0 | BD7: =MAX(0,AF7*$D7) -> 0 | BE7: =MAX(0,AG7*$D7) -> 0 | BF7: =MAX(0,AH7*$D7) -> 0 | BG7: =MAX(0,AI7*$D7) -> 0 | ... BK7: =MAX(0,AM7*$D7) -> 0
A8: Bad / 70% | B8: Bad CPA | C8: =INDEX(Inputs!$C$29:$C$31,MATCH(B8,Inputs!$A$29:$A$31,0)) -> 126 | D8: 0.7 | E8: =P8 -> 75 | F8: =U8 -> 75 | G8: =AA8 -> 75 | H8: =AM8 -> -2625 | I8: =SUM(AB8:AM8) -> -31500 | J8: =SUM(AN8:AY8) -> 0 | K8: =SUM(AZ8:BK8) -> 0 | L8: =AA8*$C8 -> 9450 | M8: =Inputs!$B$7/$C8 -> 2.3809524 | N8: =$C8/Inputs!$B$7 -> 0.42 | O8: =IF(I8>0,"OK","Loss / review") -> Loss / review | P8: =Inputs!$B$8 -> 75 | Q8: =MIN(FLOOR(P8*(1+Inputs!$B$13),1),P8+FLOOR(MAX(0,AZ8)/Inputs!$B$16,1)) -> 75 | R8: =MIN(FLOOR(Q8*(1+Inputs!$B$13),1),Q8+FLOOR(MAX(0,BA8)/Inputs!$B$16,1)) -> 75 | S8: =MIN(FLOOR(R8*(1+Inputs!$B$13),1),R8+FLOOR(MAX(0,BB8)/Inputs!$B$16,1)) -> 75 | T8: =MIN(FLOOR(S8*(1+Inputs!$B$13),1),S8+FLOOR(MAX(0,BC8)/Inputs!$B$16,1)) -> 75 | U8: =MIN(FLOOR(T8*(1+Inputs!$B$13),1),T8+FLOOR(MAX(0,BD8)/Inputs!$B$16,1)) -> 75 | V8: =MIN(FLOOR(U8*(1+Inputs!$B$13),1),U8+FLOOR(MAX(0,BE8)/Inputs!$B$16,1)) -> 75 | W8: =MIN(FLOOR(V8*(1+Inputs!$B$13),1),V8+FLOOR(MAX(0,BF8)/Inputs!$B$16,1)) -> 75 | X8: =MIN(FLOOR(W8*(1+Inputs!$B$13),1),W8+FLOOR(MAX(0,BG8)/Inputs!$B$16,1)) -> 75 | ... AA8: =MIN(FLOOR(Z8*(1+Inputs!$B$13),1),Z8+FLOOR(MAX(0,BJ8)/Inputs!$B$16,1)) -> 75 | AB8: =P8*Inputs!$B$10*Inputs!$B$7*(1-Inputs!$B$11)-P8*Inputs!$B$10*Inputs!$B$24-P8*Inputs!$B$10*$C8-Inputs!$B$12 -> -2625 | AC8: =Q8*Inputs!$B$10*Inputs!$B$7*(1-Inputs!$B$11)-Q8*Inputs!$B$10*Inputs!$B$24-Q8*Inputs!$B$10*$C8-Inputs!$B$12 -> -2625 | AD8: =R8*Inputs!$B$10*Inputs!$B$7*(1-Inputs!$B$11)-R8*Inputs!$B$10*Inputs!$B$24-R8*Inputs!$B$10*$C8-Inputs!$B$12 -> -2625 | AE8: =S8*Inputs!$B$10*Inputs!$B$7*(1-Inputs!$B$11)-S8*Inputs!$B$10*Inputs!$B$24-S8*Inputs!$B$10*$C8-Inputs!$B$12 -> -2625 | AF8: =T8*Inputs!$B$10*Inputs!$B$7*(1-Inputs!$B$11)-T8*Inputs!$B$10*Inputs!$B$24-T8*Inputs!$B$10*$C8-Inputs!$B$12 -> -2625 | AG8: =U8*Inputs!$B$10*Inputs!$B$7*(1-Inputs!$B$11)-U8*Inputs!$B$10*Inputs!$B$24-U8*Inputs!$B$10*$C8-Inputs!$B$12 -> -2625 | AH8: =V8*Inputs!$B$10*Inputs!$B$7*(1-Inputs!$B$11)-V8*Inputs!$B$10*Inputs!$B$24-V8*Inputs!$B$10*$C8-Inputs!$B$12 -> -2625 | AI8: =W8*Inputs!$B$10*Inputs!$B$7*(1-Inputs!$B$11)-W8*Inputs!$B$10*Inputs!$B$24-W8*Inputs!$B$10*$C8-Inputs!$B$12 -> -2625 | ... AM8: =AA8*Inputs!$B$10*Inputs!$B$7*(1-Inputs!$B$11)-AA8*Inputs!$B$10*Inputs!$B$24-AA8*Inputs!$B$10*$C8-Inputs!$B$12 -> -2625 | AN8: =MAX(0,AB8*(1-$D8)) -> 0 | AO8: =MAX(0,AC8*(1-$D8)) -> 0 | AP8: =MAX(0,AD8*(1-$D8)) -> 0 | AQ8: =MAX(0,AE8*(1-$D8)) -> 0 | AR8: =MAX(0,AF8*(1-$D8)) -> 0 | AS8: =MAX(0,AG8*(1-$D8)) -> 0 | AT8: =MAX(0,AH8*(1-$D8)) -> 0 | AU8: =MAX(0,AI8*(1-$D8)) -> 0 | ... AY8: =MAX(0,AM8*(1-$D8)) -> 0 | AZ8: =MAX(0,AB8*$D8) -> 0 | BA8: =MAX(0,AC8*$D8) -> 0 | BB8: =MAX(0,AD8*$D8) -> 0 | BC8: =MAX(0,AE8*$D8) -> 0 | BD8: =MAX(0,AF8*$D8) -> 0 | BE8: =MAX(0,AG8*$D8) -> 0 | BF8: =MAX(0,AH8*$D8) -> 0 | BG8: =MAX(0,AI8*$D8) -> 0 | ... BK8: =MAX(0,AM8*$D8) -> 0
A9: Base / 30% | B9: Base CPA | C9: =INDEX(Inputs!$C$29:$C$31,MATCH(B9,Inputs!$A$29:$A$31,0)) -> 96 | D9: 0.3 | E9: =P9 -> 75 | F9: =U9 -> 75 | G9: =AA9 -> 75 | H9: =AM9 -> -375 | I9: =SUM(AB9:AM9) -> -4500 | J9: =SUM(AN9:AY9) -> 0 | K9: =SUM(AZ9:BK9) -> 0 | L9: =AA9*$C9 -> 7200 | M9: =Inputs!$B$7/$C9 -> 3.125 | N9: =$C9/Inputs!$B$7 -> 0.32 | O9: =IF(I9>0,"OK","Loss / review") -> Loss / review | P9: =Inputs!$B$8 -> 75 | Q9: =MIN(FLOOR(P9*(1+Inputs!$B$13),1),P9+FLOOR(MAX(0,AZ9)/Inputs!$B$16,1)) -> 75 | R9: =MIN(FLOOR(Q9*(1+Inputs!$B$13),1),Q9+FLOOR(MAX(0,BA9)/Inputs!$B$16,1)) -> 75 | S9: =MIN(FLOOR(R9*(1+Inputs!$B$13),1),R9+FLOOR(MAX(0,BB9)/Inputs!$B$16,1)) -> 75 | T9: =MIN(FLOOR(S9*(1+Inputs!$B$13),1),S9+FLOOR(MAX(0,BC9)/Inputs!$B$16,1)) -> 75 | U9: =MIN(FLOOR(T9*(1+Inputs!$B$13),1),T9+FLOOR(MAX(0,BD9)/Inputs!$B$16,1)) -> 75 | V9: =MIN(FLOOR(U9*(1+Inputs!$B$13),1),U9+FLOOR(MAX(0,BE9)/Inputs!$B$16,1)) -> 75 | W9: =MIN(FLOOR(V9*(1+Inputs!$B$13),1),V9+FLOOR(MAX(0,BF9)/Inputs!$B$16,1)) -> 75 | X9: =MIN(FLOOR(W9*(1+Inputs!$B$13),1),W9+FLOOR(MAX(0,BG9)/Inputs!$B$16,1)) -> 75 | ... AA9: =MIN(FLOOR(Z9*(1+Inputs!$B$13),1),Z9+FLOOR(MAX(0,BJ9)/Inputs!$B$16,1)) -> 75 | AB9: =P9*Inputs!$B$10*Inputs!$B$7*(1-Inputs!$B$11)-P9*Inputs!$B$10*Inputs!$B$24-P9*Inputs!$B$10*$C9-Inputs!$B$12 -> -375 | AC9: =Q9*Inputs!$B$10*Inputs!$B$7*(1-Inputs!$B$11)-Q9*Inputs!$B$10*Inputs!$B$24-Q9*Inputs!$B$10*$C9-Inputs!$B$12 -> -375 | AD9: =R9*Inputs!$B$10*Inputs!$B$7*(1-Inputs!$B$11)-R9*Inputs!$B$10*Inputs!$B$24-R9*Inputs!$B$10*$C9-Inputs!$B$12 -> -375 | AE9: =S9*Inputs!$B$10*Inputs!$B$7*(1-Inputs!$B$11)-S9*Inputs!$B$10*Inputs!$B$24-S9*Inputs!$B$10*$C9-Inputs!$B$12 -> -375 | AF9: =T9*Inputs!$B$10*Inputs!$B$7*(1-Inputs!$B$11)-T9*Inputs!$B$10*Inputs!$B$24-T9*Inputs!$B$10*$C9-Inputs!$B$12 -> -375 | AG9: =U9*Inputs!$B$10*Inputs!$B$7*(1-Inputs!$B$11)-U9*Inputs!$B$10*Inputs!$B$24-U9*Inputs!$B$10*$C9-Inputs!$B$12 -> -375 | AH9: =V9*Inputs!$B$10*Inputs!$B$7*(1-Inputs!$B$11)-V9*Inputs!$B$10*Inputs!$B$24-V9*Inputs!$B$10*$C9-Inputs!$B$12 -> -375 | AI9: =W9*Inputs!$B$10*Inputs!$B$7*(1-Inputs!$B$11)-W9*Inputs!$B$10*Inputs!$B$24-W9*Inputs!$B$10*$C9-Inputs!$B$12 -> -375 | ... AM9: =AA9*Inputs!$B$10*Inputs!$B$7*(1-Inputs!$B$11)-AA9*Inputs!$B$10*Inputs!$B$24-AA9*Inputs!$B$10*$C9-Inputs!$B$12 -> -375 | AN9: =MAX(0,AB9*(1-$D9)) -> 0 | AO9: =MAX(0,AC9*(1-$D9)) -> 0 | AP9: =MAX(0,AD9*(1-$D9)) -> 0 | AQ9: =MAX(0,AE9*(1-$D9)) -> 0 | AR9: =MAX(0,AF9*(1-$D9)) -> 0 | AS9: =MAX(0,AG9*(1-$D9)) -> 0 | AT9: =MAX(0,AH9*(1-$D9)) -> 0 | AU9: =MAX(0,AI9*(1-$D9)) -> 0 | ... AY9: =MAX(0,AM9*(1-$D9)) -> 0 | AZ9: =MAX(0,AB9*$D9) -> 0 | BA9: =MAX(0,AC9*$D9) -> 0 | BB9: =MAX(0,AD9*$D9) -> 0 | BC9: =MAX(0,AE9*$D9) -> 0 | BD9: =MAX(0,AF9*$D9) -> 0 | BE9: =MAX(0,AG9*$D9) -> 0 | BF9: =MAX(0,AH9*$D9) -> 0 | BG9: =MAX(0,AI9*$D9) -> 0 | ... BK9: =MAX(0,AM9*$D9) -> 0
A10: Base / 50% | B10: Base CPA | C10: =INDEX(Inputs!$C$29:$C$31,MATCH(B10,Inputs!$A$29:$A$31,0)) -> 96 | D10: 0.5 | E10: =P10 -> 75 | F10: =U10 -> 75 | G10: =AA10 -> 75 | H10: =AM10 -> -375 | I10: =SUM(AB10:AM10) -> -4500 | J10: =SUM(AN10:AY10) -> 0 | K10: =SUM(AZ10:BK10) -> 0 | L10: =AA10*$C10 -> 7200 | M10: =Inputs!$B$7/$C10 -> 3.125 | N10: =$C10/Inputs!$B$7 -> 0.32 | O10: =IF(I10>0,"OK","Loss / review") -> Loss / review | P10: =Inputs!$B$8 -> 75 | Q10: =MIN(FLOOR(P10*(1+Inputs!$B$13),1),P10+FLOOR(MAX(0,AZ10)/Inputs!$B$16,1)) -> 75 | R10: =MIN(FLOOR(Q10*(1+Inputs!$B$13),1),Q10+FLOOR(MAX(0,BA10)/Inputs!$B$16,1)) -> 75 | S10: =MIN(FLOOR(R10*(1+Inputs!$B$13),1),R10+FLOOR(MAX(0,BB10)/Inputs!$B$16,1)) -> 75 | T10: =MIN(FLOOR(S10*(1+Inputs!$B$13),1),S10+FLOOR(MAX(0,BC10)/Inputs!$B$16,1)) -> 75 | U10: =MIN(FLOOR(T10*(1+Inputs!$B$13),1),T10+FLOOR(MAX(0,BD10)/Inputs!$B$16,1)) -> 75 | V10: =MIN(FLOOR(U10*(1+Inputs!$B$13),1),U10+FLOOR(MAX(0,BE10)/Inputs!$B$16,1)) -> 75 | W10: =MIN(FLOOR(V10*(1+Inputs!$B$13),1),V10+FLOOR(MAX(0,BF10)/Inputs!$B$16,1)) -> 75 | X10: =MIN(FLOOR(W10*(1+Inputs!$B$13),1),W10+FLOOR(MAX(0,BG10)/Inputs!$B$16,1)) -> 75 | ... AA10: =MIN(FLOOR(Z10*(1+Inputs!$B$13),1),Z10+FLOOR(MAX(0,BJ10)/Inputs!$B$16,1)) -> 75 | AB10: =P10*Inputs!$B$10*Inputs!$B$7*(1-Inputs!$B$11)-P10*Inputs!$B$10*Inputs!$B$24-P10*Inputs!$B$10*$C10-Inputs!$B$12 -> -375 | AC10: =Q10*Inputs!$B$10*Inputs!$B$7*(1-Inputs!$B$11)-Q10*Inputs!$B$10*Inputs!$B$24-Q10*Inputs!$B$10*$C10-Inputs!$B$12 -> -375 | AD10: =R10*Inputs!$B$10*Inputs!$B$7*(1-Inputs!$B$11)-R10*Inputs!$B$10*Inputs!$B$24-R10*Inputs!$B$10*$C10-Inputs!$B$12 -> -375 | AE10: =S10*Inputs!$B$10*Inputs!$B$7*(1-Inputs!$B$11)-S10*Inputs!$B$10*Inputs!$B$24-S10*Inputs!$B$10*$C10-Inputs!$B$12 -> -375 | AF10: =T10*Inputs!$B$10*Inputs!$B$7*(1-Inputs!$B$11)-T10*Inputs!$B$10*Inputs!$B$24-T10*Inputs!$B$10*$C10-Inputs!$B$12 -> -375 | AG10: =U10*Inputs!$B$10*Inputs!$B$7*(1-Inputs!$B$11)-U10*Inputs!$B$10*Inputs!$B$24-U10*Inputs!$B$10*$C10-Inputs!$B$12 -> -375 | AH10: =V10*Inputs!$B$10*Inputs!$B$7*(1-Inputs!$B$11)-V10*Inputs!$B$10*Inputs!$B$24-V10*Inputs!$B$10*$C10-Inputs!$B$12 -> -375 | AI10: =W10*Inputs!$B$10*Inputs!$B$7*(1-Inputs!$B$11)-W10*Inputs!$B$10*Inputs!$B$24-W10*Inputs!$B$10*$C10-Inputs!$B$12 -> -375 | ... AM10: =AA10*Inputs!$B$10*Inputs!$B$7*(1-Inputs!$B$11)-AA10*Inputs!$B$10*Inputs!$B$24-AA10*Inputs!$B$10*$C10-Inputs!$B$12 -> -375 | AN10: =MAX(0,AB10*(1-$D10)) -> 0 | AO10: =MAX(0,AC10*(1-$D10)) -> 0 | AP10: =MAX(0,AD10*(1-$D10)) -> 0 | AQ10: =MAX(0,AE10*(1-$D10)) -> 0 | AR10: =MAX(0,AF10*(1-$D10)) -> 0 | AS10: =MAX(0,AG10*(1-$D10)) -> 0 | AT10: =MAX(0,AH10*(1-$D10)) -> 0 | AU10: =MAX(0,AI10*(1-$D10)) -> 0 | ... AY10: =MAX(0,AM10*(1-$D10)) -> 0 | AZ10: =MAX(0,AB10*$D10) -> 0 | BA10: =MAX(0,AC10*$D10) -> 0 | BB10: =MAX(0,AD10*$D10) -> 0 | BC10: =MAX(0,AE10*$D10) -> 0 | BD10: =MAX(0,AF10*$D10) -> 0 | BE10: =MAX(0,AG10*$D10) -> 0 | BF10: =MAX(0,AH10*$D10) -> 0 | BG10: =MAX(0,AI10*$D10) -> 0 | ... BK10: =MAX(0,AM10*$D10) -> 0
A11: Base / 70% | B11: Base CPA | C11: =INDEX(Inputs!$C$29:$C$31,MATCH(B11,Inputs!$A$29:$A$31,0)) -> 96 | D11: 0.7 | E11: =P11 -> 75 | F11: =U11 -> 75 | G11: =AA11 -> 75 | H11: =AM11 -> -375 | I11: =SUM(AB11:AM11) -> -4500 | J11: =SUM(AN11:AY11) -> 0 | K11: =SUM(AZ11:BK11) -> 0 | L11: =AA11*$C11 -> 7200 | M11: =Inputs!$B$7/$C11 -> 3.125 | N11: =$C11/Inputs!$B$7 -> 0.32 | O11: =IF(I11>0,"OK","Loss / review") -> Loss / review | P11: =Inputs!$B$8 -> 75 | Q11: =MIN(FLOOR(P11*(1+Inputs!$B$13),1),P11+FLOOR(MAX(0,AZ11)/Inputs!$B$16,1)) -> 75 | R11: =MIN(FLOOR(Q11*(1+Inputs!$B$13),1),Q11+FLOOR(MAX(0,BA11)/Inputs!$B$16,1)) -> 75 | S11: =MIN(FLOOR(R11*(1+Inputs!$B$13),1),R11+FLOOR(MAX(0,BB11)/Inputs!$B$16,1)) -> 75 | T11: =MIN(FLOOR(S11*(1+Inputs!$B$13),1),S11+FLOOR(MAX(0,BC11)/Inputs!$B$16,1)) -> 75 | U11: =MIN(FLOOR(T11*(1+Inputs!$B$13),1),T11+FLOOR(MAX(0,BD11)/Inputs!$B$16,1)) -> 75 | V11: =MIN(FLOOR(U11*(1+Inputs!$B$13),1),U11+FLOOR(MAX(0,BE11)/Inputs!$B$16,1)) -> 75 | W11: =MIN(FLOOR(V11*(1+Inputs!$B$13),1),V11+FLOOR(MAX(0,BF11)/Inputs!$B$16,1)) -> 75 | X11: =MIN(FLOOR(W11*(1+Inputs!$B$13),1),W11+FLOOR(MAX(0,BG11)/Inputs!$B$16,1)) -> 75 | ... AA11: =MIN(FLOOR(Z11*(1+Inputs!$B$13),1),Z11+FLOOR(MAX(0,BJ11)/Inputs!$B$16,1)) -> 75 | AB11: =P11*Inputs!$B$10*Inputs!$B$7*(1-Inputs!$B$11)-P11*Inputs!$B$10*Inputs!$B$24-P11*Inputs!$B$10*$C11-Inputs!$B$12 -> -375 | AC11: =Q11*Inputs!$B$10*Inputs!$B$7*(1-Inputs!$B$11)-Q11*Inputs!$B$10*Inputs!$B$24-Q11*Inputs!$B$10*$C11-Inputs!$B$12 -> -375 | AD11: =R11*Inputs!$B$10*Inputs!$B$7*(1-Inputs!$B$11)-R11*Inputs!$B$10*Inputs!$B$24-R11*Inputs!$B$10*$C11-Inputs!$B$12 -> -375 | AE11: =S11*Inputs!$B$10*Inputs!$B$7*(1-Inputs!$B$11)-S11*Inputs!$B$10*Inputs!$B$24-S11*Inputs!$B$10*$C11-Inputs!$B$12 -> -375 | AF11: =T11*Inputs!$B$10*Inputs!$B$7*(1-Inputs!$B$11)-T11*Inputs!$B$10*Inputs!$B$24-T11*Inputs!$B$10*$C11-Inputs!$B$12 -> -375 | AG11: =U11*Inputs!$B$10*Inputs!$B$7*(1-Inputs!$B$11)-U11*Inputs!$B$10*Inputs!$B$24-U11*Inputs!$B$10*$C11-Inputs!$B$12 -> -375 | AH11: =V11*Inputs!$B$10*Inputs!$B$7*(1-Inputs!$B$11)-V11*Inputs!$B$10*Inputs!$B$24-V11*Inputs!$B$10*$C11-Inputs!$B$12 -> -375 | AI11: =W11*Inputs!$B$10*Inputs!$B$7*(1-Inputs!$B$11)-W11*Inputs!$B$10*Inputs!$B$24-W11*Inputs!$B$10*$C11-Inputs!$B$12 -> -375 | ... AM11: =AA11*Inputs!$B$10*Inputs!$B$7*(1-Inputs!$B$11)-AA11*Inputs!$B$10*Inputs!$B$24-AA11*Inputs!$B$10*$C11-Inputs!$B$12 -> -375 | AN11: =MAX(0,AB11*(1-$D11)) -> 0 | AO11: =MAX(0,AC11*(1-$D11)) -> 0 | AP11: =MAX(0,AD11*(1-$D11)) -> 0 | AQ11: =MAX(0,AE11*(1-$D11)) -> 0 | AR11: =MAX(0,AF11*(1-$D11)) -> 0 | AS11: =MAX(0,AG11*(1-$D11)) -> 0 | AT11: =MAX(0,AH11*(1-$D11)) -> 0 | AU11: =MAX(0,AI11*(1-$D11)) -> 0 | ... AY11: =MAX(0,AM11*(1-$D11)) -> 0 | AZ11: =MAX(0,AB11*$D11) -> 0 | BA11: =MAX(0,AC11*$D11) -> 0 | BB11: =MAX(0,AD11*$D11) -> 0 | BC11: =MAX(0,AE11*$D11) -> 0 | BD11: =MAX(0,AF11*$D11) -> 0 | BE11: =MAX(0,AG11*$D11) -> 0 | BF11: =MAX(0,AH11*$D11) -> 0 | BG11: =MAX(0,AI11*$D11) -> 0 | ... BK11: =MAX(0,AM11*$D11) -> 0
